<?xml version="1.0" encoding="utf-8"?>
<!-- This URDF was automatically created by SolidWorks to URDF Exporter! Originally created by Stephen Brawner (brawner@gmail.com) 
     Commit Version: 1.6.0-4-g7f85cfe  Build Version: 1.6.7995.38578
     For more information, please see http://wiki.ros.org/sw_urdf_exporter -->
<robot
  name="ACPS-URDF">
  <link
    name="base_link">
    <inertial>
      <origin
        xyz="-0.019877 0.012957 0.006213"
        rpy="0 0 0" />
      <mass
        value="0.043005" />
      <inertia
        ixx="3.5652E-06"
        ixy="-3.2723E-08"
        ixz="9.8437E-12"
        iyy="9.9719E-06"
        iyz="6.3535E-13"
        izz="8.7138E-06" />
    </inertial>
    <visual>
      <origin
        xyz="0 0 0"
        rpy="0 0 0" />
      <geometry>
        <mesh
          filename="package://ACPS-URDF/meshes/base_link.STL" />
      </geometry>
      <material
        name="">
        <color
          rgba="0.79216 0.81961 0.93333 1" />
      </material>
    </visual>
    <collision>
      <origin
        xyz="0 0 0"
        rpy="0 0 0" />
      <geometry>
        <mesh
          filename="package://ACPS-URDF/meshes/base_link.STL" />
      </geometry>
    </collision>
  </link>
  <link
    name="link_1">
    <inertial>
      <origin
        xyz="-0.01247 0.052242 0.0076389"
        rpy="0 0 0" />
      <mass
        value="0.053822" />
      <inertia
        ixx="1.0804E-05"
        ixy="9.8437E-12"
        ixz="-6.3535E-13"
        iyy="7.1817E-06"
        iyz="3.2723E-08"
        izz="1.1924E-05" />
    </inertial>
    <visual>
      <origin
        xyz="0 0 0"
        rpy="0 0 0" />
      <geometry>
        <mesh
          filename="package://ACPS-URDF/meshes/link_1.STL" />
      </geometry>
      <material
        name="">
        <color
          rgba="0.79216 0.81961 0.93333 1" />
      </material>
    </visual>
    <collision>
      <origin
        xyz="0 0 0"
        rpy="0 0 0" />
      <geometry>
        <mesh
          filename="package://ACPS-URDF/meshes/link_1.STL" />
      </geometry>
    </collision>
  </link>
  <joint
    name="theta_1"
    type="continuous">
    <origin
      xyz="-0.020018 0.00045924 0.0059483"
      rpy="1.5708 0 0" />
    <parent
      link="base_link" />
    <child
      link="link_1" />
    <axis
      xyz="0 0 0" />
    <limit
      lower="0"
      upper="0"
      effort="0"
      velocity="0" />
  </joint>
  <link
    name="link_2">
    <inertial>
      <origin
        xyz="0.026086 0.070299 0.0067412"
        rpy="0 0 0" />
      <mass
        value="0.055878" />
      <inertia
        ixx="7.9123E-06"
        ixy="9.8437E-12"
        ixz="-3.2723E-08"
        iyy="1.3121E-05"
        iyz="6.3535E-13"
        izz="1.2397E-05" />
    </inertial>
    <visual>
      <origin
        xyz="0 0 0"
        rpy="0 0 0" />
      <geometry>
        <mesh
          filename="package://ACPS-URDF/meshes/link_2.STL" />
      </geometry>
      <material
        name="">
        <color
          rgba="0.79216 0.81961 0.93333 1" />
      </material>
    </visual>
    <collision>
      <origin
        xyz="0 0 0"
        rpy="0 0 0" />
      <geometry>
        <mesh
          filename="package://ACPS-URDF/meshes/link_2.STL" />
      </geometry>
    </collision>
  </link>
  <joint
    name="theta_2"
    type="revolute">
    <origin
      xyz="0 0 0"
      rpy="0 0 0" />
    <parent
      link="link_1" />
    <child
      link="link_2" />
    <axis
      xyz="0 0 0" />
    <limit
      lower="0"
      upper="0"
      effort="0"
      velocity="0" />
  </joint>
  <link
    name="link_3">
    <inertial>
      <origin
        xyz="0.084636 0.070299 0.0076034"
        rpy="0 0 0" />
      <mass
        value="0.055878" />
      <inertia
        ixx="7.9123E-06"
        ixy="-9.8437E-12"
        ixz="3.2723E-08"
        iyy="1.3121E-05"
        iyz="6.3535E-13"
        izz="1.2397E-05" />
    </inertial>
    <visual>
      <origin
        xyz="0 0 0"
        rpy="0 0 0" />
      <geometry>
        <mesh
          filename="package://ACPS-URDF/meshes/link_3.STL" />
      </geometry>
      <material
        name="">
        <color
          rgba="0.79216 0.81961 0.93333 1" />
      </material>
    </visual>
    <collision>
      <origin
        xyz="0 0 0"
        rpy="0 0 0" />
      <geometry>
        <mesh
          filename="package://ACPS-URDF/meshes/link_3.STL" />
      </geometry>
    </collision>
  </link>
  <joint
    name="theta_3"
    type="revolute">
    <origin
      xyz="0 0 0"
      rpy="0 0 0" />
    <parent
      link="link_2" />
    <child
      link="link_3" />
    <axis
      xyz="0 0 0" />
    <limit
      lower="0"
      upper="0"
      effort="0"
      velocity="0" />
  </joint>
  <link
    name="link_4">
    <inertial>
      <origin
        xyz="4.1633E-16 0.022 -0.013893"
        rpy="0 0 0" />
      <mass
        value="0.012873" />
      <inertia
        ixx="4.4076E-06"
        ixy="-4.171E-21"
        ixz="-2.233E-20"
        iyy="2.4256E-06"
        iyz="-2.5782E-21"
        izz="4.3471E-06" />
    </inertial>
    <visual>
      <origin
        xyz="0 0 0"
        rpy="0 0 0" />
      <geometry>
        <mesh
          filename="package://ACPS-URDF/meshes/link_4.STL" />
      </geometry>
      <material
        name="">
        <color
          rgba="0.79216 0.81961 0.93333 1" />
      </material>
    </visual>
    <collision>
      <origin
        xyz="0 0 0"
        rpy="0 0 0" />
      <geometry>
        <mesh
          filename="package://ACPS-URDF/meshes/link_4.STL" />
      </geometry>
    </collision>
  </link>
  <joint
    name="theta_4"
    type="revolute">
    <origin
      xyz="0.10463 0.070299 0.029672"
      rpy="-1.5708 0 1.5708" />
    <parent
      link="link_3" />
    <child
      link="link_4" />
    <axis
      xyz="0 0 0" />
    <limit
      lower="0"
      upper="0"
      effort="0"
      velocity="0" />
  </joint>
</robot>